<?xml version="1.0" encoding="utf-8"?>
<!-- This URDF was automatically created by SolidWorks to URDF Exporter! Originally created by Stephen Brawner (brawner@gmail.com) 
     Commit Version: 1.6.0-4-g7f85cfe  Build Version: 1.6.7995.38578
     For more information, please see http://wiki.ros.org/sw_urdf_exporter -->
<robot
  name="luxuryhand_urdf_0917">
  <link
    name="base_link">
    <inertial>
      <origin
        xyz="-0.000162054672351965 0.0495949934981655 0.123001776586946"
        rpy="0 0 0" />
      <mass
        value="21.5288238970587" />
      <inertia
        ixx="0.454358398448651"
        ixy="0.000473772825612187"
        ixz="2.95148274357809E-05"
        iyy="0.331958685950884"
        iyz="-0.00566130840497637"
        izz="0.73013765984204" />
    </inertial>
    <visual>
      <origin
        xyz="0 0 0"
        rpy="0 0 0" />
      <geometry>
        <mesh
          filename="meshes/base_link.STL" />
      </geometry>
      <material
        name="">
        <color
          rgba="0.792156862745098 0.819607843137255 0.933333333333333 1" />
      </material>
    </visual>
    <collision>
      <origin
        xyz="0 0 0"
        rpy="0 0 0" />
      <geometry>
        <mesh
          filename="meshes/base_link.STL" />
      </geometry>
    </collision>
  </link>
  <link
    name="J1">
    <inertial>
      <origin
        xyz="-0.0603541831679253 0.258704060751816 -0.000969190157743438"
        rpy="0 0 0" />
      <mass
        value="53.9719618325615" />
      <inertia
        ixx="1.70398365645003"
        ixy="-0.00338718972975684"
        ixz="-0.000770567077376284"
        iyy="0.579116862993089"
        iyz="-0.0679655694994835"
        izz="1.57065492670546" />
    </inertial>
    <visual>
      <origin
        xyz="0 0 0"
        rpy="0 0 0" />
      <geometry>
        <mesh
          filename="meshes/J1.STL" />
      </geometry>
      <material
        name="">
        <color
          rgba="0.898039215686275 0.917647058823529 0.929411764705882 1" />
      </material>
    </visual>
    <collision>
      <origin
        xyz="0 0 0"
        rpy="0 0 0" />
      <geometry>
        <mesh
          filename="meshes/J1.STL" />
      </geometry>
    </collision>
  </link>
  <joint
    name="J1"
    type="revolute">
    <origin
      xyz="0 0 0.267"
      rpy="1.5707963267949 0 -1.5707963267949" />
    <parent
      link="base_link" />
    <child
      link="J1" />
    <axis
      xyz="0 1 0" />
    <limit
      lower="0"
      upper="6.28"
      effort="0"
      velocity="0" />
  </joint>
  <link
    name="J2">
    <inertial>
      <origin
        xyz="0.0855217124773731 0.373235062034317 0.0315732771170133"
        rpy="0 0 0" />
      <mass
        value="41.359901272997" />
      <inertia
        ixx="0.646598342545983"
        ixy="0.00725765787379437"
        ixz="-0.000409356278832458"
        iyy="0.310009425369267"
        iyz="0.0887613859985803"
        izz="0.649813903413905" />
    </inertial>
    <visual>
      <origin
        xyz="0 0 0"
        rpy="0 0 0" />
      <geometry>
        <mesh
          filename="meshes/J2.STL" />
      </geometry>
      <material
        name="">
        <color
          rgba="0.898039215686275 0.917647058823529 0.929411764705882 1" />
      </material>
    </visual>
    <collision>
      <origin
        xyz="0 0 0"
        rpy="0 0 0" />
      <geometry>
        <mesh
          filename="meshes/J2.STL" />
      </geometry>
    </collision>
  </link>
  <joint
    name="J2"
    type="revolute">
    <origin
      xyz="0.0235 0.25 0"
      rpy="3.1416 0 3.1416" />
    <parent
      link="J1" />
    <child
      link="J2" />
    <axis
      xyz="-1 0 0" />
    <limit
      lower="0"
      upper="6.28"
      effort="0"
      velocity="0" />
  </joint>
  <link
    name="J3">
    <inertial>
      <origin
        xyz="0.0397853851770521 0.689164700094247 -0.0590258484876579"
        rpy="0 0 0" />
      <mass
        value="83.0154089780717" />
      <inertia
        ixx="2.61029498539962"
        ixy="-0.0642451708552979"
        ixz="0.0181007715715592"
        iyy="0.34801715793667"
        iyz="-0.0299089625027216"
        izz="2.64548700828987" />
    </inertial>
    <visual>
      <origin
        xyz="0 0 0"
        rpy="0 0 0" />
      <geometry>
        <mesh
          filename="meshes/J3.STL" />
      </geometry>
      <material
        name="">
        <color
          rgba="0.898039215686275 0.917647058823529 0.929411764705882 1" />
      </material>
    </visual>
    <collision>
      <origin
        xyz="0 0 0"
        rpy="0 0 0" />
      <geometry>
        <mesh
          filename="meshes/J3.STL" />
      </geometry>
    </collision>
  </link>
  <joint
    name="J3"
    type="revolute">
    <origin
      xyz="0.0235000000000002 0.5 0.0450000000000001"
      rpy="0 -1.5707963267949 0" />
    <parent
      link="J2" />
    <child
      link="J3" />
    <axis
      xyz="-1 0 0" />
    <limit
      lower="0"
      upper="6.28"
      effort="0"
      velocity="0" />
  </joint>
  <link
    name="44">
    <inertial>
      <origin
        xyz="0.0235804424800037 0.0995064625218145 0.0440884450905126"
        rpy="0 0 0" />
      <mass
        value="0.601730479755884" />
      <inertia
        ixx="0.00130809106003844"
        ixy="9.31756207818538E-06"
        ixz="4.98667220198601E-06"
        iyy="0.000848370282751268"
        iyz="-0.000427416158804759"
        izz="0.000877126769346819" />
    </inertial>
    <visual>
      <origin
        xyz="0 0 0"
        rpy="0 0 0" />
      <geometry>
        <mesh
          filename="meshes/44.STL" />
      </geometry>
      <material
        name="">
        <color
          rgba="0.898039215686275 0.917647058823529 0.929411764705882 1" />
      </material>
    </visual>
    <collision>
      <origin
        xyz="0 0 0"
        rpy="0 0 0" />
      <geometry>
        <mesh
          filename="meshes/44.STL" />
      </geometry>
    </collision>
  </link>
  <joint
    name="44"
    type="revolute">
    <origin
      xyz="-0.387872102027654 0.999806552037383 0.103691479774955"
      rpy="2.34168598125918 0.765281674627553 -2.99413090070427" />
    <parent
      link="J3" />
    <child
      link="44" />
    <axis
      xyz="-1 0 0" />
    <limit
      lower="0"
      upper="6.28"
      effort="0"
      velocity="0" />
  </joint>
  <link
    name="43">
    <inertial>
      <origin
        xyz="-0.000920378322012638 0.191952409524569 -9.53778877312017E-06"
        rpy="0 0 0" />
      <mass
        value="0.9826000337601" />
      <inertia
        ixx="0.0151893810686327"
        ixy="-0.000497853915455481"
        ixz="2.67839853659683E-08"
        iyy="0.000675934354285286"
        iyz="-1.16509671549674E-06"
        izz="0.0146477533675474" />
    </inertial>
    <visual>
      <origin
        xyz="0 0 0"
        rpy="0 0 0" />
      <geometry>
        <mesh
          filename="meshes/43.STL" />
      </geometry>
      <material
        name="">
        <color
          rgba="0.898039215686275 0.917647058823529 0.929411764705882 1" />
      </material>
    </visual>
    <collision>
      <origin
        xyz="0 0 0"
        rpy="0 0 0" />
      <geometry>
        <mesh
          filename="meshes/43.STL" />
      </geometry>
    </collision>
  </link>
  <joint
    name="43"
    type="revolute">
    <origin
      xyz="-0.00479999995492499 0.158808388985254 0.0629062848720496"
      rpy="1.5707963267949 -1.08558565747861 -1.5707963267949" />
    <parent
      link="44" />
    <child
      link="43" />
    <axis
      xyz="1 0 0" />
    <limit
      lower="0"
      upper="6.28"
      effort="0"
      velocity="0" />
  </joint>
  <link
    name="42">
    <inertial>
      <origin
        xyz="0.00450486603662237 0.137197568248204 -1.29125286574272E-08"
        rpy="0 0 0" />
      <mass
        value="0.466934387198078" />
      <inertia
        ixx="0.00320932972831658"
        ixy="-0.000291368687908495"
        ixz="-5.78449020453842E-11"
        iyy="0.000285868868736747"
        iyz="1.94195393937052E-10"
        izz="0.00302614008485671" />
    </inertial>
    <visual>
      <origin
        xyz="0 0 0"
        rpy="0 0 0" />
      <geometry>
        <mesh
          filename="meshes/42.STL" />
      </geometry>
      <material
        name="">
        <color
          rgba="0.898039215686275 0.917647058823529 0.929411764705882 1" />
      </material>
    </visual>
    <collision>
      <origin
        xyz="0 0 0"
        rpy="0 0 0" />
      <geometry>
        <mesh
          filename="meshes/42.STL" />
      </geometry>
    </collision>
  </link>
  <joint
    name="42"
    type="revolute">
    <origin
      xyz="0.000499999912289995 0.411 0"
      rpy="0 0 0" />
    <parent
      link="43" />
    <child
      link="42" />
    <axis
      xyz="-1 0 0" />
    <limit
      lower="0"
      upper="6.28"
      effort="0"
      velocity="0" />
  </joint>
  <link
    name="41">
    <inertial>
      <origin
        xyz="-0.00503006610120627 0.142315521477699 2.02094333767722E-08"
        rpy="0 0 0" />
      <mass
        value="0.228674551880057" />
      <inertia
        ixx="0.00257593192144187"
        ixy="5.52911190034121E-06"
        ixz="1.14642260528458E-11"
        iyy="7.78710640966879E-05"
        iyz="-2.31678912653802E-10"
        izz="0.00250092383205119" />
    </inertial>
    <visual>
      <origin
        xyz="0 0 0"
        rpy="0 0 0" />
      <geometry>
        <mesh
          filename="meshes/41.STL" />
      </geometry>
      <material
        name="">
        <color
          rgba="0.898039215686275 0.917647058823529 0.929411764705882 1" />
      </material>
    </visual>
    <collision>
      <origin
        xyz="0 0 0"
        rpy="0 0 0" />
      <geometry>
        <mesh
          filename="meshes/41.STL" />
      </geometry>
    </collision>
  </link>
  <joint
    name="41"
    type="revolute">
    <origin
      xyz="0.013 0.279 0"
      rpy="0 0 0" />
    <parent
      link="42" />
    <child
      link="41" />
    <axis
      xyz="1 0 0" />
    <limit
      lower="0"
      upper="6.28"
      effort="0"
      velocity="0" />
  </joint>
  <link
    name="34">
    <inertial>
      <origin
        xyz="0.0234472767582609 0.106354146551779 0.0271426118622773"
        rpy="0 0 0" />
      <mass
        value="0.5848704637547" />
      <inertia
        ixx="0.00124681062934242"
        ixy="1.05678683000887E-05"
        ixz="6.03069227929224E-08"
        iyy="0.000469904967599495"
        iyz="-0.000284161753120328"
        izz="0.00119388611469227" />
    </inertial>
    <visual>
      <origin
        xyz="0 0 0"
        rpy="0 0 0" />
      <geometry>
        <mesh
          filename="meshes/34.STL" />
      </geometry>
      <material
        name="">
        <color
          rgba="0.898039215686275 0.917647058823529 0.929411764705882 1" />
      </material>
    </visual>
    <collision>
      <origin
        xyz="0 0 0"
        rpy="0 0 0" />
      <geometry>
        <mesh
          filename="meshes/34.STL" />
      </geometry>
    </collision>
  </link>
  <joint
    name="34"
    type="revolute">
    <origin
      xyz="-0.145553336451425 1.10733987562554 -0.0621192328845845"
      rpy="2.67703643748493 1.2077198834197 -3.10822377014945" />
    <parent
      link="J3" />
    <child
      link="34" />
    <axis
      xyz="-1 0 0" />
    <limit
      lower="0"
      upper="6.28"
      effort="0"
      velocity="0" />
  </joint>
  <link
    name="33">
    <inertial>
      <origin
        xyz="-0.000713163653423443 0.263769432054027 -7.45236368998592E-06"
        rpy="0 0 0" />
      <mass
        value="1.31712008748802" />
      <inertia
        ixx="0.035958565277887"
        ixy="-0.000726505496456917"
        ixz="2.7135532000306E-07"
        iyy="0.000934016974753022"
        iyz="1.88777102364451E-05"
        izz="0.0352084511271497" />
    </inertial>
    <visual>
      <origin
        xyz="0 0 0"
        rpy="0 0 0" />
      <geometry>
        <mesh
          filename="meshes/33.STL" />
      </geometry>
      <material
        name="">
        <color
          rgba="0.898039215686275 0.917647058823529 0.929411764705882 1" />
      </material>
    </visual>
    <collision>
      <origin
        xyz="0 0 0"
        rpy="0 0 0" />
      <geometry>
        <mesh
          filename="meshes/33.STL" />
      </geometry>
    </collision>
  </link>
  <joint
    name="33"
    type="revolute">
    <origin
      xyz="-0.00479999995492517 0.163737247319439 0.0193720679030269"
      rpy="-1.57079632679284 -1.57031143397797 1.57079632679272" />
    <parent
      link="34" />
    <child
      link="33" />
    <axis
      xyz="1 0 0" />
    <limit
      lower="0"
      upper="6.28"
      effort="0"
      velocity="0" />
  </joint>
  <link
    name="32">
    <inertial>
      <origin
        xyz="0.00297889524657813 0.210738457205825 -2.31054239629991E-08"
        rpy="0 0 0" />
      <mass
        value="0.682391054794693" />
      <inertia
        ixx="0.0102030650465216"
        ixy="-0.000497175916560071"
        ixz="-1.0873316309834E-10"
        iyy="0.000404883687037689"
        iyz="1.44529639142376E-09"
        izz="0.00991839929182711" />
    </inertial>
    <visual>
      <origin
        xyz="0 0 0"
        rpy="0 0 0" />
      <geometry>
        <mesh
          filename="meshes/32.STL" />
      </geometry>
      <material
        name="">
        <color
          rgba="0.898039215686275 0.917647058823529 0.929411764705882 1" />
      </material>
    </visual>
    <collision>
      <origin
        xyz="0 0 0"
        rpy="0 0 0" />
      <geometry>
        <mesh
          filename="meshes/32.STL" />
      </geometry>
    </collision>
  </link>
  <joint
    name="32"
    type="revolute">
    <origin
      xyz="0.00049999991228955 0.558999999999999 0"
      rpy="0 0 0" />
    <parent
      link="33" />
    <child
      link="32" />
    <axis
      xyz="-1 0 0" />
    <limit
      lower="0"
      upper="6.28"
      effort="0"
      velocity="0" />
  </joint>
  <link
    name="31">
    <inertial>
      <origin
        xyz="-0.00503006551524909 0.142315509990039 1.82896764955309E-08"
        rpy="0 0 0" />
      <mass
        value="0.228674533254763" />
      <inertia
        ixx="0.00257593152540865"
        ixy="5.52909493724437E-06"
        ixz="1.26793295372567E-11"
        iyy="7.78710619103073E-05"
        iyz="-1.59837604054254E-10"
        izz="0.00250092343574424" />
    </inertial>
    <visual>
      <origin
        xyz="0 0 0"
        rpy="0 0 0" />
      <geometry>
        <mesh
          filename="meshes/31.STL" />
      </geometry>
      <material
        name="">
        <color
          rgba="0.898039215686275 0.917647058823529 0.929411764705882 1" />
      </material>
    </visual>
    <collision>
      <origin
        xyz="0 0 0"
        rpy="0 0 0" />
      <geometry>
        <mesh
          filename="meshes/31.STL" />
      </geometry>
    </collision>
  </link>
  <joint
    name="31"
    type="revolute">
    <origin
      xyz="0.0130000000000182 0.419 0"
      rpy="0 0 0" />
    <parent
      link="32" />
    <child
      link="31" />
    <axis
      xyz="1 0 0" />
    <limit
      lower="0"
      upper="6.28"
      effort="0"
      velocity="0" />
  </joint>
  <link
    name="24">
    <inertial>
      <origin
        xyz="0.0192637742220241 0.0994316136485516 0.0466466766917903"
        rpy="0 0 0" />
      <mass
        value="0.660012391226825" />
      <inertia
        ixx="0.00170133277744437"
        ixy="2.97528165638997E-05"
        ixz="7.64837740867523E-06"
        iyy="0.000984663242191655"
        iyz="-0.000609687122843908"
        izz="0.00144254750116698" />
    </inertial>
    <visual>
      <origin
        xyz="0 0 0"
        rpy="0 0 0" />
      <geometry>
        <mesh
          filename="meshes/24.STL" />
      </geometry>
      <material
        name="">
        <color
          rgba="0.898039215686275 0.917647058823529 0.929411764705882 1" />
      </material>
    </visual>
    <collision>
      <origin
        xyz="0 0 0"
        rpy="0 0 0" />
      <geometry>
        <mesh
          filename="meshes/24.STL" />
      </geometry>
    </collision>
  </link>
  <joint
    name="24"
    type="revolute">
    <origin
      xyz="0.152474160440312 1.195 -0.1148"
      rpy="2.67703643748493 1.2077198834197 -3.10822377014945" />
    <parent
      link="J3" />
    <child
      link="24" />
    <axis
      xyz="-1 0 0" />
    <limit
      lower="0"
      upper="6.28"
      effort="0"
      velocity="0" />
  </joint>
  <link
    name="23">
    <inertial>
      <origin
        xyz="0.00114314270716198 0.280503421568113 -8.77782970909458E-06"
        rpy="0 0 0" />
      <mass
        value="1.43510756506963" />
      <inertia
        ixx="0.0454390891995773"
        ixy="-0.000856673001975266"
        ixz="3.90396133077447E-07"
        iyy="0.00110168876372508"
        iyz="2.58050967768601E-05"
        izz="0.0445403613227143" />
    </inertial>
    <visual>
      <origin
        xyz="0 0 0"
        rpy="0 0 0" />
      <geometry>
        <mesh
          filename="meshes/23.STL" />
      </geometry>
      <material
        name="">
        <color
          rgba="0.898039215686275 0.917647058823529 0.929411764705882 1" />
      </material>
    </visual>
    <collision>
      <origin
        xyz="0 0 0"
        rpy="0 0 0" />
      <geometry>
        <mesh
          filename="meshes/23.STL" />
      </geometry>
    </collision>
  </link>
  <joint
    name="23"
    type="revolute">
    <origin
      xyz="-0.0148000000000002 0.15794479572498 0.0509197056703083"
      rpy="1.5707963267949 -1.30672692427107 -1.5707963267949" />
    <parent
      link="24" />
    <child
      link="23" />
    <axis
      xyz="1 0 0" />
    <limit
      lower="0"
      upper="6.28"
      effort="0"
      velocity="0" />
  </joint>
  <link
    name="22">
    <inertial>
      <origin
        xyz="0.00271775134913654 0.216797700634566 -2.24080395766491E-08"
        rpy="0 0 0" />
      <mass
        value="0.68765830321605" />
      <inertia
        ixx="0.0106900864677109"
        ixy="-0.000529216130522426"
        ixz="-1.05524895676916E-10"
        iyy="0.000407184125791434"
        iyz="1.54027503059935E-09"
        izz="0.0104055874771164" />
    </inertial>
    <visual>
      <origin
        xyz="0 0 0"
        rpy="0 0 0" />
      <geometry>
        <mesh
          filename="meshes/22.STL" />
      </geometry>
      <material
        name="">
        <color
          rgba="0.898039215686275 0.917647058823529 0.929411764705882 1" />
      </material>
    </visual>
    <collision>
      <origin
        xyz="0 0 0"
        rpy="0 0 0" />
      <geometry>
        <mesh
          filename="meshes/22.STL" />
      </geometry>
    </collision>
  </link>
  <joint
    name="22"
    type="revolute">
    <origin
      xyz="0.00249999995736316 0.601000000000004 0"
      rpy="0 0 0" />
    <parent
      link="23" />
    <child
      link="22" />
    <axis
      xyz="-1 0 0" />
    <limit
      lower="0"
      upper="6.28"
      effort="0"
      velocity="0" />
  </joint>
  <link
    name="21">
    <inertial>
      <origin
        xyz="-0.00504759232521323 0.170284458432228 1.70786262493339E-08"
        rpy="0 0 0" />
      <mass
        value="0.254975979560504" />
      <inertia
        ixx="0.00393584126953663"
        ixy="6.61562103924652E-06"
        ixz="1.37611161329207E-11"
        iyy="8.90586450025596E-05"
        iyz="-2.26120131308233E-10"
        izz="0.00384993660682433" />
    </inertial>
    <visual>
      <origin
        xyz="0 0 0"
        rpy="0 0 0" />
      <geometry>
        <mesh
          filename="meshes/21.STL" />
      </geometry>
      <material
        name="">
        <color
          rgba="0.898039215686275 0.917647058823529 0.929411764705882 1" />
      </material>
    </visual>
    <collision>
      <origin
        xyz="0 0 0"
        rpy="0 0 0" />
      <geometry>
        <mesh
          filename="meshes/21.STL" />
      </geometry>
    </collision>
  </link>
  <joint
    name="21"
    type="revolute">
    <origin
      xyz="0.0130000000000194 0.428000000000001 0"
      rpy="0 0 0" />
    <parent
      link="22" />
    <child
      link="21" />
    <axis
      xyz="1 0 0" />
    <limit
      lower="0"
      upper="6.28"
      effort="0"
      velocity="0" />
  </joint>
  <link
    name="14">
    <inertial>
      <origin
        xyz="0.0234472748060257 0.106354153219238 0.0271426137735653"
        rpy="0 0 0" />
      <mass
        value="0.584870520281729" />
      <inertia
        ixx="0.00124681080539021"
        ixy="1.05678565519017E-05"
        ixz="6.03055663415399E-08"
        iyy="0.000469905022534379"
        iyz="-0.000284161876885498"
        izz="0.00119388625488136" />
    </inertial>
    <visual>
      <origin
        xyz="0 0 0"
        rpy="0 0 0" />
      <geometry>
        <mesh
          filename="meshes/14.STL" />
      </geometry>
      <material
        name="">
        <color
          rgba="0.898039215686275 0.917647058823529 0.929411764705882 1" />
      </material>
    </visual>
    <collision>
      <origin
        xyz="0 0 0"
        rpy="0 0 0" />
      <geometry>
        <mesh
          filename="meshes/14.STL" />
      </geometry>
    </collision>
  </link>
  <joint
    name="14"
    type="revolute">
    <origin
      xyz="0.472336167630784 1.1555709123701 -0.0995939623002705"
      rpy="-0.292070498161887 1.47161680290526 -0.211392467143742" />
    <parent
      link="J3" />
    <child
      link="14" />
    <axis
      xyz="-1 0 0" />
    <limit
      lower="0"
      upper="6.28"
      effort="0"
      velocity="0" />
  </joint>
  <link
    name="13">
    <inertial>
      <origin
        xyz="-0.000713160506434551 0.263769430801133 -7.44986420297966E-06"
        rpy="0 0 0" />
      <mass
        value="1.31712010988165" />
      <inertia
        ixx="0.0359585663187578"
        ixy="-0.000726506447987195"
        ixz="2.71528737985508E-07"
        iyy="0.000934016889303608"
        iyz="1.88781282814537E-05"
        izz="0.0352084522111661" />
    </inertial>
    <visual>
      <origin
        xyz="0 0 0"
        rpy="0 0 0" />
      <geometry>
        <mesh
          filename="meshes/13.STL" />
      </geometry>
      <material
        name="">
        <color
          rgba="0.898039215686275 0.917647058823529 0.929411764705882 1" />
      </material>
    </visual>
    <collision>
      <origin
        xyz="0 0 0"
        rpy="0 0 0" />
      <geometry>
        <mesh
          filename="meshes/13.STL" />
      </geometry>
    </collision>
  </link>
  <joint
    name="13"
    type="revolute">
    <origin
      xyz="-0.00479999995492504 0.163737247319438 0.0193720679030289"
      rpy="-1.5707963267953 -1.57031143397751 1.5707963267953" />
    <parent
      link="14" />
    <child
      link="13" />
    <axis
      xyz="1 0 0" />
    <limit
      lower="0"
      upper="6.28"
      effort="0"
      velocity="0" />
  </joint>
  <link
    name="12">
    <inertial>
      <origin
        xyz="0.00326838319615375 0.188848918175391 2.49012740718979E-07"
        rpy="0 0 0" />
      <mass
        value="0.627982183370657" />
      <inertia
        ixx="0.00763113050343618"
        ixy="-0.00043899139475755"
        ixz="-1.23393427301031E-09"
        iyy="0.000374296687737466"
        iyz="-1.5764161045848E-08"
        izz="0.00737345660373267" />
    </inertial>
    <visual>
      <origin
        xyz="0 0 0"
        rpy="0 0 0" />
      <geometry>
        <mesh
          filename="meshes/12.STL" />
      </geometry>
      <material
        name="">
        <color
          rgba="0.898039215686275 0.917647058823529 0.929411764705882 1" />
      </material>
    </visual>
    <collision>
      <origin
        xyz="0 0 0"
        rpy="0 0 0" />
      <geometry>
        <mesh
          filename="meshes/12.STL" />
      </geometry>
    </collision>
  </link>
  <joint
    name="12"
    type="revolute">
    <origin
      xyz="0.000499999957365271 0.558999999999999 0"
      rpy="0 0 0" />
    <parent
      link="13" />
    <child
      link="12" />
    <axis
      xyz="-1 0 0" />
    <limit
      lower="0"
      upper="6.28"
      effort="0"
      velocity="0" />
  </joint>
  <link
    name="11">
    <inertial>
      <origin
        xyz="-0.00503006591890831 0.142315529828402 1.82729602143938E-08"
        rpy="0 0 0" />
      <mass
        value="0.228674567484864" />
      <inertia
        ixx="0.00257593218336541"
        ixy="5.5291070922766E-06"
        ixz="1.24538883979758E-11"
        iyy="7.78710704663166E-05"
        iyz="-1.82736829391651E-10"
        izz="0.00250092408656466" />
    </inertial>
    <visual>
      <origin
        xyz="0 0 0"
        rpy="0 0 0" />
      <geometry>
        <mesh
          filename="meshes/11.STL" />
      </geometry>
      <material
        name="">
        <color
          rgba="0.898039215686275 0.917647058823529 0.929411764705882 1" />
      </material>
    </visual>
    <collision>
      <origin
        xyz="0 0 0"
        rpy="0 0 0" />
      <geometry>
        <mesh
          filename="meshes/11.STL" />
      </geometry>
    </collision>
  </link>
  <joint
    name="11"
    type="revolute">
    <origin
      xyz="0.0130000000000182 0.378000000000001 0"
      rpy="0 0 0" />
    <parent
      link="12" />
    <child
      link="11" />
    <axis
      xyz="1 0 0" />
    <limit
      lower="0"
      upper="6.28"
      effort="0"
      velocity="0" />
  </joint>
  <link
    name="55">
    <inertial>
      <origin
        xyz="0.123445799523467 -0.0309974250049863 -0.0180239393116912"
        rpy="0 0 0" />
      <mass
        value="0.579597470379413" />
      <inertia
        ixx="0.000625185179385426"
        ixy="0.000332745012655276"
        ixz="-3.05649316022471E-05"
        iyy="0.00172513791407252"
        iyz="-3.08351029289997E-06"
        izz="0.00162714567038465" />
    </inertial>
    <visual>
      <origin
        xyz="0 0 0"
        rpy="0 0 0" />
      <geometry>
        <mesh
          filename="meshes/55.STL" />
      </geometry>
      <material
        name="">
        <color
          rgba="0.898039215686275 0.917647058823529 0.929411764705882 1" />
      </material>
    </visual>
    <collision>
      <origin
        xyz="0 0 0"
        rpy="0 0 0" />
      <geometry>
        <mesh
          filename="meshes/55.STL" />
      </geometry>
    </collision>
  </link>
  <joint
    name="55"
    type="revolute">
    <origin
      xyz="0.252074118886262 0.168962691504214 0.121484379887695"
      rpy="-1.32959577200728 0.16250693878004 0.273370686595133" />
    <parent
      link="J3" />
    <child
      link="55" />
    <axis
      xyz="0 0 1" />
    <limit
      lower="0"
      upper="6.28"
      effort="0"
      velocity="0" />
  </joint>
  <link
    name="54">
    <inertial>
      <origin
        xyz="0.363981588871995 -0.000996967532939985 0.0284590033499341"
        rpy="0 0 0" />
      <mass
        value="3.79276355872235" />
      <inertia
        ixx="0.0064765408161169"
        ixy="0.00131886063626488"
        ixz="-0.0055065429927938"
        iyy="0.0579512059755492"
        iyz="0.000637870628354918"
        izz="0.054396069473432" />
    </inertial>
    <visual>
      <origin
        xyz="0 0 0"
        rpy="0 0 0" />
      <geometry>
        <mesh
          filename="meshes/54.STL" />
      </geometry>
      <material
        name="">
        <color
          rgba="0.898039215686275 0.917647058823529 0.929411764705882 1" />
      </material>
    </visual>
    <collision>
      <origin
        xyz="0 0 0"
        rpy="0 0 0" />
      <geometry>
        <mesh
          filename="meshes/54.STL" />
      </geometry>
    </collision>
  </link>
  <joint
    name="54"
    type="revolute">
    <origin
      xyz="0.16247565612759 -0.0108478446718678 0.0147999999999973"
      rpy="1.39963819876773 0 0.0880899702733852" />
    <parent
      link="55" />
    <child
      link="54" />
    <axis
      xyz="0 0.170323668694754 -0.985388171170306" />
    <limit
      lower="0"
      upper="6.28"
      effort="0"
      velocity="0" />
  </joint>
  <link
    name="53">
    <inertial>
      <origin
        xyz="0.109782138346384 -0.0209400912461452 -0.0247181258221338"
        rpy="0 0 0" />
      <mass
        value="0.554491444990991" />
      <inertia
        ixx="0.000350263001525429"
        ixy="0.000186605361608125"
        ixz="-3.04605478998284E-06"
        iyy="0.000954566888695729"
        iyz="1.82284018492541E-07"
        izz="0.000998995341145724" />
    </inertial>
    <visual>
      <origin
        xyz="0 0 0"
        rpy="0 0 0" />
      <geometry>
        <mesh
          filename="meshes/53.STL" />
      </geometry>
      <material
        name="">
        <color
          rgba="0.898039215686275 0.917647058823529 0.929411764705882 1" />
      </material>
    </visual>
    <collision>
      <origin
        xyz="0 0 0"
        rpy="0 0 0" />
      <geometry>
        <mesh
          filename="meshes/53.STL" />
      </geometry>
    </collision>
  </link>
  <joint
    name="53"
    type="revolute">
    <origin
      xyz="0.441103559406753 -0.00573018607835474 0.0343255730832036"
      rpy="-1.39652766163555 0.188282471226187 0.0329405559591387" />
    <parent
      link="54" />
    <child
      link="53" />
    <axis
      xyz="0 0 1" />
    <limit
      lower="0"
      upper="6.28"
      effort="0"
      velocity="0" />
  </joint>
  <link
    name="52">
    <inertial>
      <origin
        xyz="0.216797701679256 -2.22677334349441E-08 0.00271775176414907"
        rpy="0 0 0" />
      <mass
        value="0.687658319447831" />
      <inertia
        ixx="0.000407184129006652"
        ixy="1.53257602684704E-09"
        ixz="-0.000529216151883722"
        iyy="0.0104055876272605"
        iyz="-1.01709440132255E-10"
        izz="0.0106900866272019" />
    </inertial>
    <visual>
      <origin
        xyz="0 0 0"
        rpy="0 0 0" />
      <geometry>
        <mesh
          filename="meshes/52.STL" />
      </geometry>
      <material
        name="">
        <color
          rgba="0.898039215686275 0.917647058823529 0.929411764705882 1" />
      </material>
    </visual>
    <collision>
      <origin
        xyz="0 0 0"
        rpy="0 0 0" />
      <geometry>
        <mesh
          filename="meshes/52.STL" />
      </geometry>
    </collision>
  </link>
  <joint
    name="52"
    type="revolute">
    <origin
      xyz="0.165790228836713 -0.0127965574945122 -0.000199999957364527"
      rpy="1.5707963267949 0 -0.00449890490395274" />
    <parent
      link="53" />
    <child
      link="52" />
    <axis
      xyz="0 0 -1" />
    <limit
      lower="0"
      upper="6.28"
      effort="0"
      velocity="0" />
  </joint>
  <link
    name="51">
    <inertial>
      <origin
        xyz="0.170284434140944 1.69536769067946E-08 -0.00504759201476013"
        rpy="0 0 0" />
      <mass
        value="0.254975940041666" />
      <inertia
        ixx="8.9058633141528E-05"
        ixy="-2.21197633778571E-10"
        ixz="6.61560993313572E-06"
        iyy="0.00384993557480933"
        iyz="1.19537124881712E-11"
        izz="0.00393584022844232" />
    </inertial>
    <visual>
      <origin
        xyz="0 0 0"
        rpy="0 0 0" />
      <geometry>
        <mesh
          filename="meshes/51.STL" />
      </geometry>
      <material
        name="">
        <color
          rgba="0.898039215686275 0.917647058823529 0.929411764705882 1" />
      </material>
    </visual>
    <collision>
      <origin
        xyz="0 0 0"
        rpy="0 0 0" />
      <geometry>
        <mesh
          filename="meshes/51.STL" />
      </geometry>
    </collision>
  </link>
  <joint
    name="51"
    type="revolute">
    <origin
      xyz="0.427999999999999 0 0.0129999999999393"
      rpy="0 0 0" />
    <parent
      link="52" />
    <child
      link="51" />
    <axis
      xyz="0 0 1" />
    <limit
      lower="0"
      upper="6.28"
      effort="0"
      velocity="0" />
  </joint>
  <link
    name="25">
    <inertial>
      <origin
        xyz="0.0282092148811094 7.05936731293377E-09 -0.048128929902143"
        rpy="0 0 0" />
      <mass
        value="0.33225886549814" />
      <inertia
        ixx="0.000551203405593864"
        ixy="-5.05036603086947E-12"
        ixz="7.59022975763006E-06"
        iyy="0.000471044289188928"
        iyz="4.04157111273995E-11"
        izz="0.000101617279936732" />
    </inertial>
    <visual>
      <origin
        xyz="0 0 0"
        rpy="0 0 0" />
      <geometry>
        <mesh
          filename="meshes/25.STL" />
      </geometry>
      <material
        name="">
        <color
          rgba="1 1 1 1" />
      </material>
    </visual>
    <collision>
      <origin
        xyz="0 0 0"
        rpy="0 0 0" />
      <geometry>
        <mesh
          filename="meshes/25.STL" />
      </geometry>
    </collision>
  </link>
  <joint
    name="25"
    type="revolute">
    <origin
      xyz="0.252474160440315 1.109 -0.0307000000450749"
      rpy="3.0229941844947 -1.5707963267949 0" />
    <parent
      link="J3" />
    <child
      link="25" />
    <axis
      xyz="-1 0 0" />
    <limit
      lower="0"
      upper="6.28"
      effort="0"
      velocity="0" />
  </joint>
  <link
    name="26">
    <inertial>
      <origin
        xyz="0.0385186566001782 7.40280992062026E-09 0.041980228632829"
        rpy="0 0 0" />
      <mass
        value="0.50354869826274" />
      <inertia
        ixx="0.00152708230198695"
        ixy="5.85472969276947E-12"
        ixz="-0.00020690476595642"
        iyy="0.00139588559475363"
        iyz="9.30992421414827E-11"
        izz="0.000233252551473875" />
    </inertial>
    <visual>
      <origin
        xyz="0 0 0"
        rpy="0 0 0" />
      <geometry>
        <mesh
          filename="meshes/26.STL" />
      </geometry>
      <material
        name="">
        <color
          rgba="0.898039215686275 0.917647058823529 0.929411764705882 1" />
      </material>
    </visual>
    <collision>
      <origin
        xyz="0 0 0"
        rpy="0 0 0" />
      <geometry>
        <mesh
          filename="meshes/26.STL" />
      </geometry>
    </collision>
  </link>
  <joint
    name="26"
    type="revolute">
    <origin
      xyz="0.0498148799422739 0.853443264854616 -0.00120000000000006"
      rpy="3.1248793786405 -1.5707963267949 0" />
    <parent
      link="J3" />
    <child
      link="26" />
    <axis
      xyz="-1 0 0" />
    <limit
      lower="0"
      upper="6.28"
      effort="0"
      velocity="0" />
  </joint>
  <link
    name="35">
    <inertial>
      <origin
        xyz="0.0407153101232879 -3.68557295793437E-09 0.0346757840046049"
        rpy="0 0 0" />
      <mass
        value="0.393088821359469" />
      <inertia
        ixx="0.000998832015455755"
        ixy="-7.7913335844366E-12"
        ixz="-0.000162900587291854"
        iyy="0.000943667314468657"
        iyz="-1.49443621997577E-11"
        izz="0.000146199664753636" />
    </inertial>
    <visual>
      <origin
        xyz="0 0 0"
        rpy="0 0 0" />
      <geometry>
        <mesh
          filename="meshes/35.STL" />
      </geometry>
      <material
        name="">
        <color
          rgba="0.898039215686275 0.917647058823529 0.929411764705882 1" />
      </material>
    </visual>
    <collision>
      <origin
        xyz="0 0 0"
        rpy="0 0 0" />
      <geometry>
        <mesh
          filename="meshes/35.STL" />
      </geometry>
    </collision>
  </link>
  <joint
    name="35"
    type="revolute">
    <origin
      xyz="-0.156428089506825 0.944057792966971 0.0297656019149096"
      rpy="0.281643840834246 -1.2077198834197 0.0333688834403459" />
    <parent
      link="J3" />
    <child
      link="35" />
    <axis
      xyz="1 0 0" />
    <limit
      lower="0"
      upper="6.28"
      effort="0"
      velocity="0" />
  </joint>
</robot>